Traceback (most recent call last):
  File "C:\ALL\AppData\anaconda3\envs\mada_book\Lib\site-packages\nbclient\client.py", line 778, in _async_poll_for_reply
    msg = await ensure_async(self.kc.shell_channel.get_msg(timeout=new_timeout))
          ^^^^^^^^^^^^^^^^^^^^^^^^^^^^^^^^^^^^^^^^^^^^^^^^^^^^^^^^^^^^^^^^^^^^^^
  File "C:\ALL\AppData\anaconda3\envs\mada_book\Lib\site-packages\jupyter_core\utils\__init__.py", line 189, in ensure_async
    result = await obj
             ^^^^^^^^^
  File "C:\ALL\AppData\anaconda3\envs\mada_book\Lib\site-packages\jupyter_client\channels.py", line 315, in get_msg
    raise Empty
_queue.Empty

During handling of the above exception, another exception occurred:

Traceback (most recent call last):
  File "C:\ALL\AppData\anaconda3\envs\mada_book\Lib\site-packages\jupyter_cache\executors\utils.py", line 58, in single_nb_execution
    executenb(
  File "C:\ALL\AppData\anaconda3\envs\mada_book\Lib\site-packages\nbclient\client.py", line 1305, in execute
    return NotebookClient(nb=nb, resources=resources, km=km, **kwargs).execute()
           ^^^^^^^^^^^^^^^^^^^^^^^^^^^^^^^^^^^^^^^^^^^^^^^^^^^^^^^^^^^^^^^^^^^^^
  File "C:\ALL\AppData\anaconda3\envs\mada_book\Lib\site-packages\jupyter_core\utils\__init__.py", line 173, in wrapped
    return loop.run_until_complete(inner)
           ^^^^^^^^^^^^^^^^^^^^^^^^^^^^^^
  File "C:\ALL\AppData\anaconda3\envs\mada_book\Lib\asyncio\base_events.py", line 653, in run_until_complete
    return future.result()
           ^^^^^^^^^^^^^^^
  File "C:\ALL\AppData\anaconda3\envs\mada_book\Lib\site-packages\nbclient\client.py", line 705, in async_execute
    await self.async_execute_cell(
  File "C:\ALL\AppData\anaconda3\envs\mada_book\Lib\site-packages\nbclient\client.py", line 1001, in async_execute_cell
    exec_reply = await self.task_poll_for_reply
                 ^^^^^^^^^^^^^^^^^^^^^^^^^^^^^^
  File "C:\ALL\AppData\anaconda3\envs\mada_book\Lib\site-packages\nbclient\client.py", line 802, in _async_poll_for_reply
    error_on_timeout_execute_reply = await self._async_handle_timeout(timeout, cell)
                                     ^^^^^^^^^^^^^^^^^^^^^^^^^^^^^^^^^^^^^^^^^^^^^^^
  File "C:\ALL\AppData\anaconda3\envs\mada_book\Lib\site-packages\nbclient\client.py", line 852, in _async_handle_timeout
    raise CellTimeoutError.error_from_timeout_and_cell(
nbclient.exceptions.CellTimeoutError: A cell timed out while it was being executed, after 30 seconds.
The message was: Cell execution timed out.
Here is a preview of the cell contents:
-------------------
# moderated mediation: Is the effect of condition on belief updating mediated by evidence convincingness for Democrats ("party"==1) but not for Republicans ("party"==2)?
# let's first run the mediation model only for Democrats ("party"==1)

outcome_model = sm.GLM.from_formula("RdeltaB ~ cond*party + convincing*party", df, family=sm.families.Binomial())
mediator_model = sm.OLS.from_formula("convincing ~ cond*party", df)
moderators = {"party" : 1}
med = Mediation(outcome_model, mediator_model, "cond", "convincing", moderators=moderators).fit()
med.summary()
-------------------

